
CommandNotFoundError: Your shell has not been properly configured to use 'conda activate'.
To initialize your shell, run

    $ conda init <SHELL_NAME>

Currently supported shells are:
  - bash
  - fish
  - tcsh
  - xonsh
  - zsh
  - powershell

See 'conda init --help' for more information and options.

IMPORTANT: You may need to close and restart your shell after running 'conda init'.


/home/ponsmoll/pba764/.conda/envs/shape2vec/lib/python3.9/site-packages/torch/distributed/launch.py:208: FutureWarning: The module torch.distributed.launch is deprecated
and will be removed in future. Use torchrun.
Note that --use-env is set by default in torchrun.
If your script expects `--local-rank` argument to be set, please
change it to read from `os.environ['LOCAL_RANK']` instead. See 
https://pytorch.org/docs/stable/distributed.html#launch-utility for 
further instructions

  main()
/home/ponsmoll/pba764/.conda/envs/shape2vec/lib/python3.9/site-packages/timm/models/layers/__init__.py:48: FutureWarning: Importing from timm.models.layers is deprecated, please import via timm.layers
  warnings.warn(f"Importing from {__name__} is deprecated, please import via timm.layers", FutureWarning)
Traceback (most recent call last):
  File "/mnt/lustre/home/ponsmoll/pba764/projects/3DShape2VecSet/main_ae_garmentcode.py", line 258, in <module>
    main(args)
  File "/mnt/lustre/home/ponsmoll/pba764/projects/3DShape2VecSet/main_ae_garmentcode.py", line 98, in main
    misc.init_distributed_mode(args)
  File "/mnt/lustre/home/ponsmoll/pba764/projects/3DShape2VecSet/util/misc.py", line 240, in init_distributed_mode
    torch.cuda.set_device(args.gpu)
  File "/home/ponsmoll/pba764/.conda/envs/shape2vec/lib/python3.9/site-packages/torch/cuda/__init__.py", line 478, in set_device
    torch._C._cuda_setDevice(device)
  File "/home/ponsmoll/pba764/.conda/envs/shape2vec/lib/python3.9/site-packages/torch/cuda/__init__.py", line 319, in _lazy_init
    torch._C._cuda_init()
RuntimeError: Found no NVIDIA driver on your system. Please check that you have an NVIDIA GPU and installed a driver from http://www.nvidia.com/Download/index.aspx
E0328 17:59:39.179308 4156945 /mnt/lustre/home/ponsmoll/pba764/.conda/envs/shape2vec/lib/python3.9/site-packages/torch/distributed/elastic/multiprocessing/api.py:869] failed (exitcode: 1) local_rank: 0 (pid: 4156951) of binary: /home/ponsmoll/pba764/.conda/envs/shape2vec/bin/python3
Traceback (most recent call last):
  File "/home/ponsmoll/pba764/.conda/envs/shape2vec/lib/python3.9/runpy.py", line 197, in _run_module_as_main
    return _run_code(code, main_globals, None,
  File "/home/ponsmoll/pba764/.conda/envs/shape2vec/lib/python3.9/runpy.py", line 87, in _run_code
    exec(code, run_globals)
  File "/home/ponsmoll/pba764/.conda/envs/shape2vec/lib/python3.9/site-packages/torch/distributed/launch.py", line 208, in <module>
    main()
  File "/home/ponsmoll/pba764/.conda/envs/shape2vec/lib/python3.9/site-packages/typing_extensions.py", line 2853, in wrapper
    return arg(*args, **kwargs)
  File "/home/ponsmoll/pba764/.conda/envs/shape2vec/lib/python3.9/site-packages/torch/distributed/launch.py", line 204, in main
    launch(args)
  File "/home/ponsmoll/pba764/.conda/envs/shape2vec/lib/python3.9/site-packages/torch/distributed/launch.py", line 189, in launch
    run(args)
  File "/home/ponsmoll/pba764/.conda/envs/shape2vec/lib/python3.9/site-packages/torch/distributed/run.py", line 910, in run
    elastic_launch(
  File "/home/ponsmoll/pba764/.conda/envs/shape2vec/lib/python3.9/site-packages/torch/distributed/launcher/api.py", line 138, in __call__
    return launch_agent(self._config, self._entrypoint, list(args))
  File "/home/ponsmoll/pba764/.conda/envs/shape2vec/lib/python3.9/site-packages/torch/distributed/launcher/api.py", line 269, in launch_agent
    raise ChildFailedError(
torch.distributed.elastic.multiprocessing.errors.ChildFailedError: 
============================================================
main_ae_garmentcode.py FAILED
------------------------------------------------------------
Failures:
  <NO_OTHER_FAILURES>
------------------------------------------------------------
Root Cause (first observed failure):
[0]:
  time      : 2025-03-28_17:59:39
  host      : galvani-cn002.sdn
  rank      : 0 (local_rank: 0)
  exitcode  : 1 (pid: 4156951)
  error_file: <N/A>
  traceback : To enable traceback see: https://pytorch.org/docs/stable/elastic/errors.html
============================================================
srun: error: galvani-cn002: task 0: Exited with exit code 1
srun: Terminating StepId=1282001.0
